<?xml version="1.0" encoding="utf-8"?>
<!-- This URDF was automatically created by SolidWorks to URDF Exporter! Originally created by Stephen Brawner (brawner@gmail.com) 
     Commit Version: 1.6.0-1-g15f4949  Build Version: 1.6.7594.29634
     For more information, please see http://wiki.ros.org/sw_urdf_exporter -->
<robot
  name="Articulated_Robot">
  <link
    name="Base">
    <inertial>
      <origin
        xyz="-0.000241876643301109 -6.10622663543836E-16 0.0969341006571471"
        rpy="0 0 0" />
      <mass
        value="38.0424280241323" />
      <inertia
        ixx="0.996427665526993"
        ixy="-7.73722966261546E-18"
        ixz="0.00163848669097482"
        iyy="0.994713501397636"
        iyz="2.95205184749133E-15"
        izz="1.43268743827097" />
    </inertial>
    <visual>
      <origin
        xyz="0 0 0"
        rpy="0 0 0" />
      <geometry>
        <mesh
          filename="package://Articulated_Robot/meshes/Base.STL" />
      </geometry>
      <material
        name="">
        <color
          rgba="1 1 0 1" />
      </material>
    </visual>
    <collision>
      <origin
        xyz="0 0 0"
        rpy="0 0 0" />
      <geometry>
        <mesh
          filename="package://Articulated_Robot/meshes/Base.STL" />
      </geometry>
    </collision>
  </link>
  <link
    name="Link_1">
    <inertial>
      <origin
        xyz="1.34712694721539E-07 -0.00139412573638886 0.431577138697582"
        rpy="0 0 0" />
      <mass
        value="21.1243682894282" />
      <inertia
        ixx="0.957844964275292"
        ixy="-4.6834736463498E-08"
        ixz="-3.39511365837944E-07"
        iyy="0.994116691119153"
        iyz="0.00824257555295901"
        izz="0.128724196326701" />
    </inertial>
    <visual>
      <origin
        xyz="0 0 0"
        rpy="0 0 0" />
      <geometry>
        <mesh
          filename="package://Articulated_Robot/meshes/Link_1.STL" />
      </geometry>
      <material
        name="">
        <color
          rgba="0 1 0 1" />
      </material>
    </visual>
    <collision>
      <origin
        xyz="0 0 0"
        rpy="0 0 0" />
      <geometry>
        <mesh
          filename="package://Articulated_Robot/meshes/Link_1.STL" />
      </geometry>
    </collision>
  </link>
  <joint
    name="J1"
    type="continuous">
    <origin
      xyz="0 0 0"
      rpy="0 0 0" />
    <parent
      link="Base" />
    <child
      link="Link_1" />
    <axis
      xyz="0 0 1" />
  </joint>
  <link
    name="Link_2">
    <inertial>
      <origin
        xyz="-2.78926416519276E-07 -0.0994409555192519 0.920141115293976"
        rpy="0 0 0" />
      <mass
        value="35.0853621411493" />
      <inertia
        ixx="11.3161350422394"
        ixy="-1.55047251608056E-06"
        ixz="-8.82504373391087E-06"
        iyy="11.3837250958261"
        iyz="-0.0349327721881474"
        izz="0.12376353988556" />
    </inertial>
    <visual>
      <origin
        xyz="0 0 0"
        rpy="0 0 0" />
      <geometry>
        <mesh
          filename="package://Articulated_Robot/meshes/Link_2.STL" />
      </geometry>
      <material
        name="">
        <color
          rgba="1 0 0 1" />
      </material>
    </visual>
    <collision>
      <origin
        xyz="0 0 0"
        rpy="0 0 0" />
      <geometry>
        <mesh
          filename="package://Articulated_Robot/meshes/Link_2.STL" />
      </geometry>
    </collision>
  </link>
  <joint
    name="J2"
    type="continuous">
    <origin
      xyz="0 0 0.71145"
      rpy="0 0 0" />
    <parent
      link="Link_1" />
    <child
      link="Link_2" />
    <axis
      xyz="0 -1 0" />
  </joint>
  <link
    name="Link_3">
    <inertial>
      <origin
        xyz="1.58816629458602E-07 0.000377300916462264 0.665802041181273"
        rpy="0 0 0" />
      <mass
        value="25.9784378302758" />
      <inertia
        ixx="4.64792902173367"
        ixy="-1.09450409206981E-06"
        ixz="2.48485732722899E-06"
        iyy="4.70068581201351"
        iyz="0.006527354765011"
        izz="0.0914426967821872" />
    </inertial>
    <visual>
      <origin
        xyz="0 0 0"
        rpy="0 0 0" />
      <geometry>
        <mesh
          filename="package://Articulated_Robot/meshes/Link_3.STL" />
      </geometry>
      <material
        name="">
        <color
          rgba="0 0 1 1" />
      </material>
    </visual>
    <collision>
      <origin
        xyz="0 0 0"
        rpy="0 0 0" />
      <geometry>
        <mesh
          filename="package://Articulated_Robot/meshes/Link_3.STL" />
      </geometry>
    </collision>
  </link>
  <joint
    name="J3"
    type="continuous">
    <origin
      xyz="0 0 1.7995"
      rpy="0 0 0" />
    <parent
      link="Link_2" />
    <child
      link="Link_3" />
    <axis
      xyz="0 1 0" />
  </joint>
  <link
    name="End_Effector">
    <inertial>
      <origin
        xyz="-4.9960036108132E-16 -2.27595720048157E-15 -0.0125000000000006"
        rpy="0 0 0" />
      <mass
        value="0.34817477042468" />
      <inertia
        ixx="0.000333846091111613"
        ixy="-2.45071247059807E-20"
        ixz="-5.07758786819072E-20"
        iyy="0.000995949683839979"
        iyz="-2.71698290588505E-21"
        izz="0.00129352756969902" />
    </inertial>
    <visual>
      <origin
        xyz="0 0 0"
        rpy="0 0 0" />
      <geometry>
        <mesh
          filename="package://Articulated_Robot/meshes/End_Effector.STL" />
      </geometry>
      <material
        name="">
        <color
          rgba="1 0 1 1" />
      </material>
    </visual>
    <collision>
      <origin
        xyz="0 0 0"
        rpy="0 0 0" />
      <geometry>
        <mesh
          filename="package://Articulated_Robot/meshes/End_Effector.STL" />
      </geometry>
    </collision>
  </link>
  <joint
    name="F1"
    type="fixed">
    <origin
      xyz="0 0 1.425"
      rpy="0 0 0" />
    <parent
      link="Link_3" />
    <child
      link="End_Effector" />
    <axis
      xyz="0 0 0" />
  </joint>
</robot>