<?xml version="1.0" encoding="utf-8"?>
<!-- This URDF was automatically created by SolidWorks to URDF Exporter! Originally created by Stephen Brawner (brawner@gmail.com) 
     Commit Version: 1.6.0-1-g15f4949  Build Version: 1.6.7594.29634
     For more information, please see http://wiki.ros.org/sw_urdf_exporter -->
<robot
  name="Polar_Robot">
  <link
    name="Base">
    <inertial>
      <origin
        xyz="-0.000270388097905583 -1.66533453693773E-16 -1.96639513094953"
        rpy="0 0 0" />
      <mass
        value="38.0370424922611" />
      <inertia
        ixx="0.996251572071299"
        ixy="5.23572695976942E-17"
        ixz="0.00183162497118519"
        iyy="0.994324660656797"
        iyz="8.5713540873415E-16"
        izz="1.43246631952246" />
    </inertial>
    <visual>
      <origin
        xyz="0 0 0"
        rpy="0 0 0" />
      <geometry>
        <mesh
          filename="package://Polar_Robot/meshes/Base.STL" />
      </geometry>
      <material
        name="">
        <color
          rgba="1 1 0 1" />
      </material>
    </visual>
    <collision>
      <origin
        xyz="0 0 0"
        rpy="0 0 0" />
      <geometry>
        <mesh
          filename="package://Polar_Robot/meshes/Base.STL" />
      </geometry>
    </collision>
  </link>
  <link
    name="Link_1">
    <inertial>
      <origin
        xyz="0.000531579148819683 1.0216652301942E-08 1.15021527463313"
        rpy="0 0 0" />
      <mass
        value="55.4053905279187" />
      <inertia
        ixx="25.0151986713678"
        ixy="3.10114403599607E-07"
        ixz="-0.0268926087915857"
        iyy="24.8517442692666"
        iyz="-8.93435507097765E-07"
        izz="0.308183677204965" />
    </inertial>
    <visual>
      <origin
        xyz="0 0 0"
        rpy="0 0 0" />
      <geometry>
        <mesh
          filename="package://Polar_Robot/meshes/Link_1.STL" />
      </geometry>
      <material
        name="">
        <color
          rgba="0 1 0 1" />
      </material>
    </visual>
    <collision>
      <origin
        xyz="0 0 0"
        rpy="0 0 0" />
      <geometry>
        <mesh
          filename="package://Polar_Robot/meshes/Link_1.STL" />
      </geometry>
    </collision>
  </link>
  <joint
    name="J1"
    type="continuous">
    <origin
      xyz="0 0 -2.0633"
      rpy="0 0 0" />
    <parent
      link="Base" />
    <child
      link="Link_1" />
    <axis
      xyz="0 0 1" />
  </joint>
  <link
    name="Link_2">
    <inertial>
      <origin
        xyz="0.121196728745009 1.11022302462516E-16 0"
        rpy="0 0 0" />
      <mass
        value="2.23230091830128" />
      <inertia
        ixx="0.0103685011478766"
        ixy="-2.74957760687209E-18"
        ixz="3.92947890310864E-19"
        iyy="0.00858058811342199"
        iyz="-4.6296680582396E-19"
        izz="0.00959621311342197" />
    </inertial>
    <visual>
      <origin
        xyz="0 0 0"
        rpy="0 0 0" />
      <geometry>
        <mesh
          filename="package://Polar_Robot/meshes/Link_2.STL" />
      </geometry>
      <material
        name="">
        <color
          rgba="1 0 0 1" />
      </material>
    </visual>
    <collision>
      <origin
        xyz="0 0 0"
        rpy="0 0 0" />
      <geometry>
        <mesh
          filename="package://Polar_Robot/meshes/Link_2.STL" />
      </geometry>
    </collision>
  </link>
  <joint
    name="J2"
    type="continuous">
    <origin
      xyz="0 0 2.0633"
      rpy="0 0 0" />
    <parent
      link="Link_1" />
    <child
      link="Link_2" />
    <axis
      xyz="1 0 0" />
  </joint>
  <link
    name="Link_3">
    <inertial>
      <origin
        xyz="0.199121856849533 5.55111512312578E-17 0.851367974982562"
        rpy="0 0 0" />
      <mass
        value="26.8687168146928" />
      <inertia
        ixx="10.2875221281938"
        ixy="1.27745302534405E-18"
        ixz="-0.0227187464895494"
        iyy="10.2836069397478"
        iyz="-7.8936468260585E-17"
        izz="0.0697509981348238" />
    </inertial>
    <visual>
      <origin
        xyz="0 0 0"
        rpy="0 0 0" />
      <geometry>
        <mesh
          filename="package://Polar_Robot/meshes/Link_3.STL" />
      </geometry>
      <material
        name="">
        <color
          rgba="0 0 0.752941176470588 1" />
      </material>
    </visual>
    <collision>
      <origin
        xyz="0 0 0"
        rpy="0 0 0" />
      <geometry>
        <mesh
          filename="package://Polar_Robot/meshes/Link_3.STL" />
      </geometry>
    </collision>
  </link>
  <joint
    name="J3"
    type="prismatic">
    <origin
      xyz="0 0 0"
      rpy="0 0 0" />
    <parent
      link="Link_2" />
    <child
      link="Link_3" />
    <axis
      xyz="0 0 1" />
    <limit
      lower="0"
      upper="0"
      effort="0"
      velocity="0" />
  </joint>
  <link
    name="End_Effector">
    <inertial>
      <origin
        xyz="0.173563625454221 -5.55111512312578E-17 -0.0250000000000004"
        rpy="0 0 0" />
      <mass
        value="1.0935840734641" />
      <inertia
        ixx="0.00225787980080187"
        ixy="-4.29275075951513E-19"
        ixz="1.16942283792537E-18"
        iyy="0.00225562354894145"
        iyz="6.31805644457427E-20"
        izz="0.00405784331913328" />
    </inertial>
    <visual>
      <origin
        xyz="0 0 0"
        rpy="0 0 0" />
      <geometry>
        <mesh
          filename="package://Polar_Robot/meshes/End_Effector.STL" />
      </geometry>
      <material
        name="">
        <color
          rgba="1 0 1 1" />
      </material>
    </visual>
    <collision>
      <origin
        xyz="0 0 0"
        rpy="0 0 0" />
      <geometry>
        <mesh
          filename="package://Polar_Robot/meshes/End_Effector.STL" />
      </geometry>
    </collision>
  </link>
  <joint
    name="F1"
    type="fixed">
    <origin
      xyz="0 0 1.9749"
      rpy="0 0 0" />
    <parent
      link="Link_3" />
    <child
      link="End_Effector" />
    <axis
      xyz="0 0 0" />
  </joint>
</robot>